Workbook

Sheet Hoja1
A1: Regla
A2: Integrante | B2: diámetro interno (mm) | C2: e Dint | D2: diámetro externo (mm) | E2: e Dext | F2: h (mm) | G2: e h | H2: ∆X (mm)
A3: 1 | B3: 13 | C3: =$H3/B3 -> 0.076923077 | D3: 20 | E3: =$H3/D3 -> 0.05 | F3: 51 | G3: =$H3/F3 -> 0.019607843 | H3: 1 | M3: Pi Regla | N3: =ROUNDDOWN(PI(),3) -> 3.141
A4: 2 | B4: 13 | C4: =$H4/B4 -> 0.076923077 | D4: 20 | E4: =$H4/D4 -> 0.05 | F4: 50 | G4: =$H4/F4 -> 0.02 | H4: 1
A5: 3 | B5: 14 | C5: =$H5/B5 -> 0.071428571 | D5: 20 | E5: =$H5/D5 -> 0.05 | F5: 51 | G5: =$H5/F5 -> 0.019607843 | H5: 1
A6: 4 | B6: 13 | C6: =$H6/B6 -> 0.076923077 | D6: 20 | E6: =$H6/D6 -> 0.05 | F6: 51 | G6: =$H6/F6 -> 0.019607843 | H6: 1
A7: 5 | B7: 13 | C7: =$H7/B7 -> 0.076923077 | D7: 20 | E7: =$H7/D7 -> 0.05 | F7: 51 | G7: =$H7/F7 -> 0.019607843 | H7: 1
A8: 6 | B8: 13 | C8: =$H8/B8 -> 0.076923077 | D8: 20 | E8: =$H8/D8 -> 0.05 | F8: 51 | G8: =$H8/F8 -> 0.019607843 | H8: 1
A9: 7 | B9: 13 | C9: =$H9/B9 -> 0.076923077 | D9: 20 | E9: =$H9/D9 -> 0.05 | F9: 50 | G9: =$H9/F9 -> 0.02 | H9: 1
A10: 8 | B10: 13 | C10: =$H10/B10 -> 0.076923077 | D10: 20 | E10: =$H10/D10 -> 0.05 | F10: 50 | G10: =$H10/F10 -> 0.02 | H10: 1
A11: 9 | B11: 14 | C11: =$H11/B11 -> 0.071428571 | D11: 20 | E11: =$H11/D11 -> 0.05 | F11: 51 | G11: =$H11/F11 -> 0.019607843 | H11: 1 | J11: Vo Regla
A12: 10 | B12: 14 | C12: =$H12/B12 -> 0.071428571 | D12: 20 | E12: =$H12/D12 -> 0.05 | F12: 50 | G12: =$H12/F12 -> 0.02 | H12: 1 | J12: Ve Rep | K12: Vi Rep | L12: Vn Rep
B13: DIo = 13mm | D13: DEo = 20mm | F13: Ho = 51mm | J13: =20*20*N3*51/4/1000 -> 16.0191 | K13: =N3*13*13*51/4/1000 -> 6.7680697 | L13: =J13-K13 -> 9.2510303
A14: Calibre
A15: Integrante | B15: diámetro interno (mm) | C15: e Dint | D15: diámetro externo (mm) | E15: e Dext | F15: h (mm) | G15: e h | H15: ∆X (mm)
A16: 1 | B16: 13 | C16: =$H16/B16 -> 0.0015384615 | D16: 20.4 | E16: =$H16/D16 -> 0.00098039216 | F16: 50.8 | G16: =$H16/F16 -> 0.00039370079 | H16: 0.02 | M16: Pi Calibre | N16: =ROUNDDOWN(PI(),5) -> 3.14159
A17: 2 | B17: 12.9 | C17: =$H17/B17 -> 0.0015503876 | D17: 20.4 | E17: =$H17/D17 -> 0.00098039216 | F17: 50.9 | G17: =$H17/F17 -> 0.00039292731 | H17: 0.02
A18: 3 | B18: 12.9 | C18: =$H18/B18 -> 0.0015503876 | D18: 20.16 | E18: =$H18/D18 -> 0.00099206349 | F18: 50.8 | G18: =$H18/F18 -> 0.00039370079 | H18: 0.02
A19: 4 | B19: 12.8 | C19: =$H19/B19 -> 0.0015625 | D19: 20.2 | E19: =$H19/D19 -> 0.00099009901 | F19: 50.8 | G19: =$H19/F19 -> 0.00039370079 | H19: 0.02
A20: 5 | B20: 12.4 | C20: =$H20/B20 -> 0.0016129032 | D20: 20.2 | E20: =$H20/D20 -> 0.00099009901 | F20: 50.8 | G20: =$H20/F20 -> 0.00039370079 | H20: 0.02
A21: 6 | B21: 12.52 | C21: =$H21/B21 -> 0.0015974441 | D21: 20.2 | E21: =$H21/D21 -> 0.00099009901 | F21: 50.72 | G21: =$H21/F21 -> 0.00039432177 | H21: 0.02
A22: 7 | B22: 12.9 | C22: =$H22/B22 -> 0.0015503876 | D22: 20.2 | E22: =$H22/D22 -> 0.00099009901 | F22: 50.88 | G22: =$H22/F22 -> 0.00039308176 | H22: 0.02
A23: 8 | B23: 13 | C23: =$H23/B23 -> 0.0015384615 | D23: 20.4 | E23: =$H23/D23 -> 0.00098039216 | F23: 51 | G23: =$H23/F23 -> 0.00039215686 | H23: 0.02
A24: 9 | B24: 12.8 | C24: =$H24/B24 -> 0.0015625 | D24: 20.2 | E24: =$H24/D24 -> 0.00099009901 | F24: 50.8 | G24: =$H24/F24 -> 0.00039370079 | H24: 0.02 | J24: Vo Calibre
A25: 10 | B25: 12.8 | C25: =$H25/B25 -> 0.0015625 | D25: 20.2 | E25: =$H25/D25 -> 0.00099009901 | F25: 50.8 | G25: =$H25/F25 -> 0.00039370079 | H25: 0.02 | J25: Ve Rep | K25: Vi Rep | L25: Vn Rep
A26: DIo | B26: =AVERAGE(B16:B25) -> 12.802 | C26: DEo | D26: =AVERAGE(D16:D25) -> 20.256 | E26: Ho | F26: =AVERAGE(F16:F25) -> 50.83 | J26: =D26*D26*N16*F26/4/1000 -> 16.380117 | K26: =B26*B26*N16*F26/4/1000 -> 6.5428245 | L26: =J26-K26 -> 9.8372926
A27: Regla | I27: Calibre
A28: Integrante | B28: Vdi(cm3) | C28: eVdi | D28: Vde(cm3) | E28: eVde | F28: V(cm3) | G28: eV | H28: ∆V (cm3) | I28: Integrante | J28: Vdi(cm3) | K28: ∆Vdi (cm3) | L28: Vde(cm3) | M28: ∆Vde (cm3) | N28: V(cm3) | O28: eV | P28: ∆V (cm3)
A29: 1 | B29: =(ROUNDDOWN(PI(),3)*POWER(B3/2,2)*$F3)/1000 -> 6.7680697 | C29: =(2*C3+G3) -> 0.173454 | D29: =ROUNDDOWN(PI(),3)*POWER(D3/2,2)*$F3/1000 -> 16.0191 | E29: =(2*E3+G3) -> 0.11960784 | F29: =D29-B29 -> 9.2510303 | G29: =H29/F29 -> 0.33401239 | H29: =B29*C29+D29*E29 -> 3.0899588 | I29: 1 | J29: =ROUNDDOWN(PI(),3)*POWER(B16/2,2)*$F16/1000 -> 6.7415283 | K29: =(C16*2+G16) -> 0.0034706239 | L29: =ROUNDDOWN(PI(),5)*POWER(D16/2,2)*$F16/1000 -> 16.604032 | M29: =E16*2+G16 -> 0.0023544851 | N29: =L29-J29 -> 9.8625037 | O29: =P29/N29 -> 0.0063362465 | P29: =J29*K29+L29*M29 -> 0.062491255
A30: 2 | B30: =(ROUNDDOWN(PI(),3)*POWER(B4/2,2)*$F4)/1000 -> 6.6353625 | C30: =(2*C4+G4) -> 0.17384615 | D30: =ROUNDDOWN(PI(),3)*POWER(D4/2,2)*$F4/1000 -> 15.705 | E30: =(2*E4+G4) -> 0.12 | F30: =D30-B30 -> 9.0696375 | G30: =H30/F30 -> 0.33497835 | H30: =B30*C30+D30*E30 -> 3.0381323 | I30: 2 | J30: =ROUNDDOWN(PI(),3)*POWER(B17/2,2)*$F17/1000 -> 6.6512787 | K30: =(C17*2+G17) -> 0.0034937025 | L30: =ROUNDDOWN(PI(),5)*POWER(D17/2,2)*$F17/1000 -> 16.636717 | M30: =E17*2+G17 -> 0.0023537116 | N30: =L30-J30 -> 9.9854384 | O30: =P30/N30 -> 0.0062486614 | P30: =J30*K30+L30*M30 -> 0.062395624
A31: 3 | B31: =(ROUNDDOWN(PI(),3)*POWER(B5/2,2)*$F5)/1000 -> 7.849359 | C31: =(2*C5+G5) -> 0.16246499 | D31: =ROUNDDOWN(PI(),3)*POWER(D5/2,2)*$F5/1000 -> 16.0191 | E31: =(2*E5+G5) -> 0.11960784 | F31: =D31-B31 -> 8.169741 | G31: =H31/F31 -> 0.39061899 | H31: =B31*C31+D31*E31 -> 3.191256 | I31: 3 | J31: =ROUNDDOWN(PI(),3)*POWER(B18/2,2)*$F18/1000 -> 6.6382114 | K31: =(C18*2+G18) -> 0.003494476 | L31: =ROUNDDOWN(PI(),5)*POWER(D18/2,2)*$F18/1000 -> 16.215647 | M31: =E18*2+G18 -> 0.0023778278 | N31: =L31-J31 -> 9.5774356 | O31: =P31/N31 -> 0.0064479771 | P31: =J31*K31+L31*M31 -> 0.061755086
A32: 4 | B32: =(ROUNDDOWN(PI(),3)*POWER(B6/2,2)*$F6)/1000 -> 6.7680697 | C32: =(2*C6+G6) -> 0.173454 | D32: =ROUNDDOWN(PI(),3)*POWER(D6/2,2)*$F6/1000 -> 16.0191 | E32: =(2*E6+G6) -> 0.11960784 | F32: =D32-B32 -> 9.2510303 | G32: =H32/F32 -> 0.33401239 | H32: =B32*C32+D32*E32 -> 3.0899588 | I32: 4 | J32: =ROUNDDOWN(PI(),3)*POWER(B19/2,2)*$F19/1000 -> 6.5356923 | K32: =(C19*2+G19) -> 0.0035187008 | L32: =ROUNDDOWN(PI(),5)*POWER(D19/2,2)*$F19/1000 -> 16.280059 | M32: =E19*2+G19 -> 0.0023738988 | N32: =L32-J32 -> 9.7443664 | O32: =P32/N32 -> 0.0063261535 | P32: =J32*K32+L32*M32 -> 0.061644357
A33: 5 | B33: =(ROUNDDOWN(PI(),3)*POWER(B7/2,2)*$F7)/1000 -> 6.7680697 | C33: =(2*C7+G7) -> 0.173454 | D33: =ROUNDDOWN(PI(),3)*POWER(D7/2,2)*$F7/1000 -> 16.0191 | E33: =(2*E7+G7) -> 0.11960784 | F33: =D33-B33 -> 9.2510303 | G33: =H33/F33 -> 0.33401239 | H33: =B33*C33+D33*E33 -> 3.0899588 | I33: 5 | J33: =ROUNDDOWN(PI(),3)*POWER(B20/2,2)*$F20/1000 -> 6.133594 | K33: =(C20*2+G20) -> 0.0036195072 | L33: =ROUNDDOWN(PI(),5)*POWER(D20/2,2)*$F20/1000 -> 16.280059 | M33: =E20*2+G20 -> 0.0023738988 | N33: =L33-J33 -> 10.146465 | O33: =P33/N33 -> 0.0059969459 | P33: =J33*K33+L33*M33 -> 0.0608478
A34: 6 | B34: =(ROUNDDOWN(PI(),3)*POWER(B8/2,2)*$F8)/1000 -> 6.7680697 | C34: =(2*C8+G8) -> 0.173454 | D34: =ROUNDDOWN(PI(),3)*POWER(D8/2,2)*$F8/1000 -> 16.0191 | E34: =(2*E8+G8) -> 0.11960784 | F34: =D34-B34 -> 9.2510303 | G34: =H34/F34 -> 0.33401239 | H34: =B34*C34+D34*E34 -> 3.0899588 | I34: 6 | J34: =ROUNDDOWN(PI(),3)*POWER(B21/2,2)*$F21/1000 -> 6.2430361 | K34: =(C21*2+G21) -> 0.0035892099 | L34: =ROUNDDOWN(PI(),5)*POWER(D21/2,2)*$F21/1000 -> 16.254421 | M34: =E21*2+G21 -> 0.0023745198 | N34: =L34-J34 -> 10.011385 | O34: =P34/N34 -> 0.0060934639 | P34: =J34*K34+L34*M34 -> 0.061004011
A35: 7 | B35: =(ROUNDDOWN(PI(),3)*POWER(B9/2,2)*$F9)/1000 -> 6.6353625 | C35: =(2*C9+G9) -> 0.17384615 | D35: =ROUNDDOWN(PI(),3)*POWER(D9/2,2)*$F9/1000 -> 15.705 | E35: =(2*E9+G9) -> 0.12 | F35: =D35-B35 -> 9.0696375 | G35: =H35/F35 -> 0.33497835 | H35: =B35*C35+D35*E35 -> 3.0381323 | I35: 7 | J35: =ROUNDDOWN(PI(),3)*POWER(B22/2,2)*$F22/1000 -> 6.6486653 | K35: =(C22*2+G22) -> 0.003493857 | L35: =ROUNDDOWN(PI(),5)*POWER(D22/2,2)*$F22/1000 -> 16.305697 | M35: =E22*2+G22 -> 0.0023732798 | N35: =L35-J35 -> 9.6570313 | O35: =P35/N35 -> 0.0064126814 | P35: =J35*K35+L35*M35 -> 0.061927465
A36: 8 | B36: =(ROUNDDOWN(PI(),3)*POWER(B10/2,2)*$F10)/1000 -> 6.6353625 | C36: =(2*C10+G10) -> 0.17384615 | D36: =ROUNDDOWN(PI(),3)*POWER(D10/2,2)*$F10/1000 -> 15.705 | E36: =(2*E10+G10) -> 0.12 | F36: =D36-B36 -> 9.0696375 | G36: =H36/F36 -> 0.33497835 | H36: =B36*C36+D36*E36 -> 3.0381323 | I36: 8 | J36: =ROUNDDOWN(PI(),3)*POWER(B23/2,2)*$F23/1000 -> 6.7680697 | K36: =(C23*2+G23) -> 0.0034690799 | L36: =ROUNDDOWN(PI(),5)*POWER(D23/2,2)*$F23/1000 -> 16.669402 | M36: =E23*2+G23 -> 0.0023529412 | N36: =L36-J36 -> 9.9013325 | O36: =P36/N36 -> 0.0063325919 | P36: =J36*K36+L36*M36 -> 0.062701098
A37: 9 | B37: =(ROUNDDOWN(PI(),3)*POWER(B11/2,2)*$F11)/1000 -> 7.849359 | C37: =(2*C11+G11) -> 0.16246499 | D37: =ROUNDDOWN(PI(),3)*POWER(D11/2,2)*$F11/1000 -> 16.0191 | E37: =(2*E11+G11) -> 0.11960784 | F37: =D37-B37 -> 8.169741 | G37: =H37/F37 -> 0.39061899 | H37: =B37*C37+D37*E37 -> 3.191256 | I37: 9 | J37: =ROUNDDOWN(PI(),3)*POWER(B24/2,2)*$F24/1000 -> 6.5356923 | K37: =(C24*2+G24) -> 0.0035187008 | L37: =ROUNDDOWN(PI(),5)*POWER(D24/2,2)*$F24/1000 -> 16.280059 | M37: =E24*2+G24 -> 0.0023738988 | N37: =L37-J37 -> 9.7443664 | O37: =P37/N37 -> 0.0063261535 | P37: =J37*K37+L37*M37 -> 0.061644357
A38: 10 | B38: =(ROUNDDOWN(PI(),3)*POWER(B12/2,2)*$F12)/1000 -> 7.69545 | C38: =(2*C12+G12) -> 0.16285714 | D38: =ROUNDDOWN(PI(),3)*POWER(D12/2,2)*$F12/1000 -> 15.705 | E38: =(2*E12+G12) -> 0.12 | F38: =D38-B38 -> 8.00955 | G38: =H38/F38 -> 0.39176471 | H38: =B38*C38+D38*E38 -> 3.137859 | I38: 10 | J38: =ROUNDDOWN(PI(),3)*POWER(B25/2,2)*$F25/1000 -> 6.5356923 | K38: =(C25*2+G25) -> 0.0035187008 | L38: =ROUNDDOWN(PI(),5)*POWER(D25/2,2)*$F25/1000 -> 16.280059 | M38: =E25*2+G25 -> 0.0023738988 | N38: =L38-J38 -> 9.7443664 | O38: =P38/N38 -> 0.0063261535 | P38: =J38*K38+L38*M38 -> 0.061644357
A42: Probeta | H42: Probeta
A43: Integrante | B43: Vi (cm3) | C43: eVi | D43: Vf (cm3) | E43: eVf | F43: ∆V (cm3) | H43: Vpieza(cm3) | I43: eVpieza | J43: ∆V (cm3)
...

Sheet Gráficas
B2: Integrante | C2: V(cm3) | D2: =Hoja1!H28 -> ∆V (cm3) | G2: Vo
B3: 1 | C3: =Hoja1!F29 -> 9.2510303 | D3: =Hoja1!H29 -> 3.0899588 | E3: =C3-D3 -> 6.1610715 | F3: =C3+D3 -> 12.340989 | G3: =Hoja1!$L$13 -> 9.2510303
B4: 2 | C4: =Hoja1!F30 -> 9.0696375 | D4: =Hoja1!H30 -> 3.0381323 | E4: =C4-D4 -> 6.0315053 | F4: =C4+D4 -> 12.10777 | G4: =Hoja1!$L$13 -> 9.2510303
B5: 3 | C5: =Hoja1!F31 -> 8.169741 | D5: =Hoja1!H31 -> 3.191256 | E5: =C5-D5 -> 4.978485 | F5: =C5+D5 -> 11.360997 | G5: =Hoja1!$L$13 -> 9.2510303
B6: 4 | C6: =Hoja1!F32 -> 9.2510303 | D6: =Hoja1!H32 -> 3.0899588 | E6: =C6-D6 -> 6.1610715 | F6: =C6+D6 -> 12.340989 | G6: =Hoja1!$L$13 -> 9.2510303
B7: 5 | C7: =Hoja1!F33 -> 9.2510303 | D7: =Hoja1!H33 -> 3.0899588 | E7: =C7-D7 -> 6.1610715 | F7: =C7+D7 -> 12.340989 | G7: =Hoja1!$L$13 -> 9.2510303
B8: 6 | C8: =Hoja1!F34 -> 9.2510303 | D8: =Hoja1!H34 -> 3.0899588 | E8: =C8-D8 -> 6.1610715 | F8: =C8+D8 -> 12.340989 | G8: =Hoja1!$L$13 -> 9.2510303
B9: 7 | C9: =Hoja1!F35 -> 9.0696375 | D9: =Hoja1!H35 -> 3.0381323 | E9: =C9-D9 -> 6.0315053 | F9: =C9+D9 -> 12.10777 | G9: =Hoja1!$L$13 -> 9.2510303
B10: 8 | C10: =Hoja1!F36 -> 9.0696375 | D10: =Hoja1!H36 -> 3.0381323 | E10: =C10-D10 -> 6.0315053 | F10: =C10+D10 -> 12.10777 | G10: =Hoja1!$L$13 -> 9.2510303
B11: 9 | C11: =Hoja1!F37 -> 8.169741 | D11: =Hoja1!H37 -> 3.191256 | E11: =C11-D11 -> 4.978485 | F11: =C11+D11 -> 11.360997 | G11: =Hoja1!$L$13 -> 9.2510303
B12: 10 | C12: =Hoja1!F38 -> 8.00955 | D12: =Hoja1!H38 -> 3.137859 | E12: =C12-D12 -> 4.871691 | F12: =C12+D12 -> 11.147409 | G12: =Hoja1!$L$13 -> 9.2510303
B14: Integrante | C14: V(cm3) | D14: ∆V (cm3)
B15: 1 | C15: =Hoja1!N29 -> 9.8625037 | D15: =Hoja1!P29 -> 0.062491255 | E15: =C15-D15 -> 9.8000124 | F15: =C15+D15 -> 9.924995 | G15: 9.8372926
B16: 2 | C16: =Hoja1!N30 -> 9.9854384 | D16: =Hoja1!P30 -> 0.062395624 | E16: =C16-D16 -> 9.9230427 | F16: =C16+D16 -> 10.047834 | G16: 9.8372926
B17: 3 | C17: =Hoja1!N31 -> 9.5774356 | D17: =Hoja1!P31 -> 0.061755086 | E17: =C17-D17 -> 9.5156806 | F17: =C17+D17 -> 9.6391907 | G17: 9.8372926
B18: 4 | C18: =Hoja1!N32 -> 9.7443664 | D18: =Hoja1!P32 -> 0.061644357 | E18: =C18-D18 -> 9.682722 | F18: =C18+D18 -> 9.8060107 | G18: 9.8372926
B19: 5 | C19: =Hoja1!N33 -> 10.146465 | D19: =Hoja1!P33 -> 0.0608478 | E19: =C19-D19 -> 10.085617 | F19: =C19+D19 -> 10.207312 | G19: 9.8372926
B20: 6 | C20: =Hoja1!N34 -> 10.011385 | D20: =Hoja1!P34 -> 0.061004011 | E20: =C20-D20 -> 9.9503807 | F20: =C20+D20 -> 10.072389 | G20: 9.8372926
B21: 7 | C21: =Hoja1!N35 -> 9.6570313 | D21: =Hoja1!P35 -> 0.061927465 | E21: =C21-D21 -> 9.5951038 | F21: =C21+D21 -> 9.7189588 | G21: 9.8372926
B22: 8 | C22: =Hoja1!N36 -> 9.9013325 | D22: =Hoja1!P36 -> 0.062701098 | E22: =C22-D22 -> 9.8386314 | F22: =C22+D22 -> 9.9640336 | G22: 9.8372926
B23: 9 | C23: =Hoja1!N37 -> 9.7443664 | D23: =Hoja1!P37 -> 0.061644357 | E23: =C23-D23 -> 9.682722 | F23: =C23+D23 -> 9.8060107 | G23: 9.8372926
B24: 10 | C24: =Hoja1!N38 -> 9.7443664 | D24: =Hoja1!P38 -> 0.061644357 | E24: =C24-D24 -> 9.682722 | F24: =C24+D24 -> 9.8060107 | G24: 9.8372926
